[2025-06-30T09:46:47.511+0000] {local_task_job_runner.py:120} INFO - ::group::Pre task execution logs
[2025-06-30T09:46:47.535+0000] {taskinstance.py:2073} INFO - Dependencies all met for dep_context=non-requeueable deps ti=<TaskInstance: dbt_run_checkout_pipeline.auto_run_dbt manual__2025-06-30T09:10:13.494775+00:00 [queued]>
[2025-06-30T09:46:47.644+0000] {taskinstance.py:2073} INFO - Dependencies all met for dep_context=requeueable deps ti=<TaskInstance: dbt_run_checkout_pipeline.auto_run_dbt manual__2025-06-30T09:10:13.494775+00:00 [queued]>
[2025-06-30T09:46:47.645+0000] {taskinstance.py:2303} INFO - Starting attempt 1 of 3
[2025-06-30T09:46:47.669+0000] {taskinstance.py:2327} INFO - Executing <Task(BashOperator): auto_run_dbt> on 2025-06-30 09:10:13.494775+00:00
[2025-06-30T09:46:47.676+0000] {standard_task_runner.py:63} INFO - Started process 753 to run task
[2025-06-30T09:46:47.678+0000] {standard_task_runner.py:90} INFO - Running: ['***', 'tasks', 'run', 'dbt_run_checkout_pipeline', 'auto_run_dbt', 'manual__2025-06-30T09:10:13.494775+00:00', '--job-id', '40', '--raw', '--subdir', 'DAGS_FOLDER/automatic_run_dbt.py', '--cfg-path', '/tmp/tmpwe184800']
[2025-06-30T09:46:47.680+0000] {standard_task_runner.py:91} INFO - Job 40: Subtask auto_run_dbt
[2025-06-30T09:46:47.690+0000] {logging_mixin.py:188} WARNING - /home/***/.local/lib/python3.11/site-packages/***/settings.py:195 DeprecationWarning: The sql_alchemy_conn option in [core] has been moved to the sql_alchemy_conn option in [database] - the old setting has been used, but please update your config.
[2025-06-30T09:46:47.719+0000] {task_command.py:426} INFO - Running <TaskInstance: dbt_run_checkout_pipeline.auto_run_dbt manual__2025-06-30T09:10:13.494775+00:00 [running]> on host 8f966ca0121e
[2025-06-30T09:46:47.787+0000] {taskinstance.py:2644} INFO - Exporting env vars: AIRFLOW_CTX_DAG_OWNER='hosi04' AIRFLOW_CTX_DAG_ID='dbt_run_checkout_pipeline' AIRFLOW_CTX_TASK_ID='auto_run_dbt' AIRFLOW_CTX_EXECUTION_DATE='2025-06-30T09:10:13.494775+00:00' AIRFLOW_CTX_TRY_NUMBER='1' AIRFLOW_CTX_DAG_RUN_ID='manual__2025-06-30T09:10:13.494775+00:00'
[2025-06-30T09:46:47.788+0000] {taskinstance.py:430} INFO - ::endgroup::
[2025-06-30T09:46:47.796+0000] {subprocess.py:63} INFO - Tmp dir root location: /tmp
[2025-06-30T09:46:47.797+0000] {subprocess.py:75} INFO - Running command: ['/usr/bin/bash', '-c', 'cd /opt/***/dbt && dbt run --profiles-dir /opt/***/.dbt/']
[2025-06-30T09:46:47.809+0000] {subprocess.py:86} INFO - Output:
[2025-06-30T09:46:49.337+0000] {subprocess.py:93} INFO - [0m09:46:49  Running with dbt=1.10.2
[2025-06-30T09:46:49.536+0000] {subprocess.py:93} INFO - [0m09:46:49  Registered adapter: clickhouse=1.9.2
[2025-06-30T09:46:50.043+0000] {subprocess.py:93} INFO - [0m09:46:50  Found 4 models, 2 sources, 476 macros
[2025-06-30T09:46:50.044+0000] {subprocess.py:93} INFO - [0m09:46:50
[2025-06-30T09:46:50.045+0000] {subprocess.py:93} INFO - [0m09:46:50  Concurrency: 1 threads (target='dev')
[2025-06-30T09:46:50.045+0000] {subprocess.py:93} INFO - [0m09:46:50
[2025-06-30T09:46:50.524+0000] {subprocess.py:93} INFO - [0m09:46:50  1 of 4 START sql table model `tracking_problem_stg`.`stg_add_to_cart` .......... [RUN]
[2025-06-30T09:46:50.601+0000] {subprocess.py:93} INFO - [0m09:46:50  1 of 4 OK created sql table model `tracking_problem_stg`.`stg_add_to_cart` ..... [[32mOK[0m in 0.08s]
[2025-06-30T09:46:50.602+0000] {subprocess.py:93} INFO - [0m09:46:50  2 of 4 START sql table model `tracking_problem_stg`.`stg_checkout_items` ....... [RUN]
[2025-06-30T09:46:50.624+0000] {subprocess.py:93} INFO - [0m09:46:50  2 of 4 OK created sql table model `tracking_problem_stg`.`stg_checkout_items` .. [[32mOK[0m in 0.02s]
[2025-06-30T09:46:50.625+0000] {subprocess.py:93} INFO - [0m09:46:50  3 of 4 START sql table model `tracking_problem_int`.`int_checkout_items` ....... [RUN]
[2025-06-30T09:46:50.649+0000] {subprocess.py:93} INFO - [0m09:46:50  3 of 4 OK created sql table model `tracking_problem_int`.`int_checkout_items` .. [[32mOK[0m in 0.02s]
[2025-06-30T09:46:50.650+0000] {subprocess.py:93} INFO - [0m09:46:50  4 of 4 START sql table model `tracking_problem_mart`.`mart_checkout_items` ..... [RUN]
[2025-06-30T09:46:50.662+0000] {subprocess.py:93} INFO - [0m09:46:50  4 of 4 ERROR creating sql table model `tracking_problem_mart`.`mart_checkout_items`  [[31mERROR[0m in 0.01s]
[2025-06-30T09:46:50.665+0000] {subprocess.py:93} INFO - [0m09:46:50
[2025-06-30T09:46:50.666+0000] {subprocess.py:93} INFO - [0m09:46:50  Finished running 4 table models in 0 hours 0 minutes and 0.62 seconds (0.62s).
[2025-06-30T09:46:50.685+0000] {subprocess.py:93} INFO - [0m09:46:50
[2025-06-30T09:46:50.685+0000] {subprocess.py:93} INFO - [0m09:46:50  [31mCompleted with 1 error, 0 partial successes, and 0 warnings:[0m
[2025-06-30T09:46:50.686+0000] {subprocess.py:93} INFO - [0m09:46:50
[2025-06-30T09:46:50.686+0000] {subprocess.py:93} INFO - [0m09:46:50  [31mFailure in model mart_checkout_items (models/mart/checkout/mart_checkout_items.sql)[0m
[2025-06-30T09:46:50.686+0000] {subprocess.py:93} INFO - [0m09:46:50    Database Error in model mart_checkout_items (models/mart/checkout/mart_checkout_items.sql)
[2025-06-30T09:46:50.686+0000] {subprocess.py:93} INFO -   HTTPDriver for http://clickhouse:8123 received ClickHouse error code 215
[2025-06-30T09:46:50.687+0000] {subprocess.py:93} INFO -    Code: 215, e.displayText() = DB::Exception: Column `timestamp` is not under aggregate function and not in GROUP BY: While processing user_id, session_id, timestamp, product_name, product_brand, count() AS total_items, sum(quantity) AS total_quantity, sum(total_value) AS total_revenue, sum(multiIf(is_high_value_item, 1, 0)) AS high_value_item_count (version 21.8.14.5 (official build))
[2025-06-30T09:46:50.687+0000] {subprocess.py:93} INFO -   compiled code at target/run/dbt_tracking_event/models/mart/checkout/mart_checkout_items.sql
[2025-06-30T09:46:50.687+0000] {subprocess.py:93} INFO - [0m09:46:50
[2025-06-30T09:46:50.687+0000] {subprocess.py:93} INFO - [0m09:46:50    compiled code at target/compiled/dbt_tracking_event/models/mart/checkout/mart_checkout_items.sql
[2025-06-30T09:46:50.687+0000] {subprocess.py:93} INFO - [0m09:46:50
[2025-06-30T09:46:50.687+0000] {subprocess.py:93} INFO - [0m09:46:50  Done. PASS=3 WARN=0 ERROR=1 SKIP=0 NO-OP=0 TOTAL=4
[2025-06-30T09:46:52.350+0000] {subprocess.py:93} INFO - Traceback (most recent call last):
[2025-06-30T09:46:52.351+0000] {subprocess.py:93} INFO -   File "/home/***/.local/bin/dbt", line 8, in <module>
[2025-06-30T09:46:52.351+0000] {subprocess.py:93} INFO -     sys.exit(cli())
[2025-06-30T09:46:52.352+0000] {subprocess.py:93} INFO -              ^^^^^
[2025-06-30T09:46:52.352+0000] {subprocess.py:93} INFO -   File "/home/***/.local/lib/python3.11/site-packages/click/core.py", line 1157, in __call__
[2025-06-30T09:46:52.352+0000] {subprocess.py:93} INFO -     return self.main(*args, **kwargs)
[2025-06-30T09:46:52.352+0000] {subprocess.py:93} INFO -            ^^^^^^^^^^^^^^^^^^^^^^^^^^
[2025-06-30T09:46:52.352+0000] {subprocess.py:93} INFO -   File "/home/***/.local/lib/python3.11/site-packages/click/core.py", line 1078, in main
[2025-06-30T09:46:52.352+0000] {subprocess.py:93} INFO -     rv = self.invoke(ctx)
[2025-06-30T09:46:52.352+0000] {subprocess.py:93} INFO -          ^^^^^^^^^^^^^^^^
[2025-06-30T09:46:52.352+0000] {subprocess.py:93} INFO -   File "/home/***/.local/lib/python3.11/site-packages/click/core.py", line 1688, in invoke
[2025-06-30T09:46:52.352+0000] {subprocess.py:93} INFO -     return _process_result(sub_ctx.command.invoke(sub_ctx))
[2025-06-30T09:46:52.353+0000] {subprocess.py:93} INFO -                            ^^^^^^^^^^^^^^^^^^^^^^^^^^^^^^^
[2025-06-30T09:46:52.353+0000] {subprocess.py:93} INFO -   File "/home/***/.local/lib/python3.11/site-packages/click/core.py", line 1434, in invoke
[2025-06-30T09:46:52.353+0000] {subprocess.py:93} INFO -     return ctx.invoke(self.callback, **ctx.params)
[2025-06-30T09:46:52.353+0000] {subprocess.py:93} INFO -            ^^^^^^^^^^^^^^^^^^^^^^^^^^^^^^^^^^^^^^^
[2025-06-30T09:46:52.353+0000] {subprocess.py:93} INFO -   File "/home/***/.local/lib/python3.11/site-packages/click/core.py", line 783, in invoke
[2025-06-30T09:46:52.353+0000] {subprocess.py:93} INFO -     return __callback(*args, **kwargs)
[2025-06-30T09:46:52.353+0000] {subprocess.py:93} INFO -            ^^^^^^^^^^^^^^^^^^^^^^^^^^^
[2025-06-30T09:46:52.353+0000] {subprocess.py:93} INFO -   File "/home/***/.local/lib/python3.11/site-packages/click/decorators.py", line 33, in new_func
[2025-06-30T09:46:52.353+0000] {subprocess.py:93} INFO -     return f(get_current_context(), *args, **kwargs)
[2025-06-30T09:46:52.354+0000] {subprocess.py:93} INFO -            ^^^^^^^^^^^^^^^^^^^^^^^^^^^^^^^^^^^^^^^^^
[2025-06-30T09:46:52.354+0000] {subprocess.py:93} INFO -   File "/home/***/.local/lib/python3.11/site-packages/dbt/cli/main.py", line 149, in wrapper
[2025-06-30T09:46:52.354+0000] {subprocess.py:93} INFO -     return func(*args, **kwargs)
[2025-06-30T09:46:52.354+0000] {subprocess.py:93} INFO -            ^^^^^^^^^^^^^^^^^^^^^
[2025-06-30T09:46:52.354+0000] {subprocess.py:93} INFO -   File "/home/***/.local/lib/python3.11/site-packages/dbt/cli/requires.py", line 190, in wrapper
[2025-06-30T09:46:52.354+0000] {subprocess.py:93} INFO -     fire_event(
[2025-06-30T09:46:52.354+0000] {subprocess.py:93} INFO -   File "/home/***/.local/lib/python3.11/site-packages/dbt_common/events/functions.py", line 142, in fire_event
[2025-06-30T09:46:52.354+0000] {subprocess.py:93} INFO -     get_event_manager().fire_event(
[2025-06-30T09:46:52.354+0000] {subprocess.py:93} INFO -   File "/home/***/.local/lib/python3.11/site-packages/dbt_common/events/event_manager.py", line 56, in fire_event
[2025-06-30T09:46:52.354+0000] {subprocess.py:93} INFO -     msg = msg_from_base_event(e, level=level)
[2025-06-30T09:46:52.355+0000] {subprocess.py:93} INFO -           ^^^^^^^^^^^^^^^^^^^^^^^^^^^^^^^^^^^
[2025-06-30T09:46:52.355+0000] {subprocess.py:93} INFO -   File "/home/***/.local/lib/python3.11/site-packages/dbt_common/events/base_types.py", line 140, in msg_from_base_event
[2025-06-30T09:46:52.355+0000] {subprocess.py:93} INFO -     "msg": event.message(),
[2025-06-30T09:46:52.355+0000] {subprocess.py:93} INFO -            ^^^^^^^^^^^^^^^
[2025-06-30T09:46:52.355+0000] {subprocess.py:93} INFO -   File "/home/***/.local/lib/python3.11/site-packages/dbt/events/types.py", line 2400, in message
[2025-06-30T09:46:52.355+0000] {subprocess.py:93} INFO -     return f"Resource report: {self.to_json()}"
[2025-06-30T09:46:52.355+0000] {subprocess.py:93} INFO -                                ^^^^^^^^^^^^^^
[2025-06-30T09:46:52.355+0000] {subprocess.py:93} INFO -   File "/home/***/.local/lib/python3.11/site-packages/dbt_common/events/base_types.py", line 98, in to_json
[2025-06-30T09:46:52.355+0000] {subprocess.py:93} INFO -     return MessageToJson(
[2025-06-30T09:46:52.356+0000] {subprocess.py:93} INFO -            ^^^^^^^^^^^^^^
[2025-06-30T09:46:52.356+0000] {subprocess.py:93} INFO - TypeError: MessageToJson() got an unexpected keyword argument 'always_print_fields_with_no_presence'
[2025-06-30T09:46:52.853+0000] {subprocess.py:97} INFO - Command exited with return code 1
[2025-06-30T09:46:52.854+0000] {taskinstance.py:441} INFO - ::group::Post task execution logs
[2025-06-30T09:46:52.862+0000] {taskinstance.py:2890} ERROR - Task failed with exception
Traceback (most recent call last):
  File "/home/airflow/.local/lib/python3.11/site-packages/airflow/models/taskinstance.py", line 465, in _execute_task
    result = _execute_callable(context=context, **execute_callable_kwargs)
             ^^^^^^^^^^^^^^^^^^^^^^^^^^^^^^^^^^^^^^^^^^^^^^^^^^^^^^^^^^^^^
  File "/home/airflow/.local/lib/python3.11/site-packages/airflow/models/taskinstance.py", line 432, in _execute_callable
    return execute_callable(context=context, **execute_callable_kwargs)
           ^^^^^^^^^^^^^^^^^^^^^^^^^^^^^^^^^^^^^^^^^^^^^^^^^^^^^^^^^^^^
  File "/home/airflow/.local/lib/python3.11/site-packages/airflow/models/baseoperator.py", line 400, in wrapper
    return func(self, *args, **kwargs)
           ^^^^^^^^^^^^^^^^^^^^^^^^^^^
  File "/home/airflow/.local/lib/python3.11/site-packages/airflow/operators/bash.py", line 243, in execute
    raise AirflowException(
airflow.exceptions.AirflowException: Bash command failed. The command returned a non-zero exit code 1.
[2025-06-30T09:46:52.864+0000] {taskinstance.py:1205} INFO - Marking task as UP_FOR_RETRY. dag_id=dbt_run_checkout_pipeline, task_id=auto_run_dbt, execution_date=20250630T091013, start_date=20250630T094647, end_date=20250630T094652
[2025-06-30T09:46:52.880+0000] {standard_task_runner.py:110} ERROR - Failed to execute job 40 for task auto_run_dbt (Bash command failed. The command returned a non-zero exit code 1.; 753)
[2025-06-30T09:46:52.926+0000] {local_task_job_runner.py:240} INFO - Task exited with return code 1
[2025-06-30T09:46:52.939+0000] {taskinstance.py:3482} INFO - 0 downstream tasks scheduled from follow-on schedule check
[2025-06-30T09:46:52.939+0000] {local_task_job_runner.py:222} INFO - ::endgroup::
